[2024-11-15T21:26:45.985+0000] {local_task_job_runner.py:123} INFO - ::group::Pre task execution logs
[2024-11-15T21:26:46.143+0000] {taskinstance.py:2613} INFO - Dependencies all met for dep_context=non-requeueable deps ti=<TaskInstance: stock_sentiment_analysis.process_data scheduled__2023-10-11T00:00:00+00:00 [queued]>
[2024-11-15T21:26:46.202+0000] {taskinstance.py:2613} INFO - Dependencies all met for dep_context=requeueable deps ti=<TaskInstance: stock_sentiment_analysis.process_data scheduled__2023-10-11T00:00:00+00:00 [queued]>
[2024-11-15T21:26:46.204+0000] {taskinstance.py:2866} INFO - Starting attempt 1 of 2
[2024-11-15T21:26:46.299+0000] {taskinstance.py:2889} INFO - Executing <Task(PythonOperator): process_data> on 2023-10-11 00:00:00+00:00
[2024-11-15T21:26:46.386+0000] {warnings.py:112} WARNING - /home/***/.local/lib/python3.12/site-packages/***/task/task_runner/standard_task_runner.py:70: DeprecationWarning: This process (pid=190) is multi-threaded, use of fork() may lead to deadlocks in the child.
  pid = os.fork()

[2024-11-15T21:26:46.484+0000] {standard_task_runner.py:72} INFO - Started process 232 to run task
[2024-11-15T21:26:46.490+0000] {standard_task_runner.py:104} INFO - Running: ['***', 'tasks', 'run', 'stock_sentiment_analysis', 'process_data', 'scheduled__2023-10-11T00:00:00+00:00', '--job-id', '33', '--raw', '--subdir', 'DAGS_FOLDER/ETL_saham_dag.py', '--cfg-path', '/tmp/tmpixu2byec']
[2024-11-15T21:26:46.509+0000] {standard_task_runner.py:105} INFO - Job 33: Subtask process_data
[2024-11-15T21:26:46.914+0000] {task_command.py:467} INFO - Running <TaskInstance: stock_sentiment_analysis.process_data scheduled__2023-10-11T00:00:00+00:00 [running]> on host 50375b572a3b
[2024-11-15T21:26:47.678+0000] {taskinstance.py:3132} INFO - Exporting env vars: AIRFLOW_CTX_DAG_OWNER='***' AIRFLOW_CTX_DAG_ID='stock_sentiment_analysis' AIRFLOW_CTX_TASK_ID='process_data' AIRFLOW_CTX_EXECUTION_DATE='2023-10-11T00:00:00+00:00' AIRFLOW_CTX_TRY_NUMBER='1' AIRFLOW_CTX_DAG_RUN_ID='scheduled__2023-10-11T00:00:00+00:00'
[2024-11-15T21:26:47.694+0000] {logging_mixin.py:190} INFO - Task instance is in running state
[2024-11-15T21:26:47.697+0000] {logging_mixin.py:190} INFO -  Previous state of the Task instance: queued
[2024-11-15T21:26:47.704+0000] {logging_mixin.py:190} INFO - Current task name:process_data state:running start_date:2024-11-15 21:26:46.145944+00:00
[2024-11-15T21:26:47.708+0000] {logging_mixin.py:190} INFO - Dag name:stock_sentiment_analysis and current dag run status:running
[2024-11-15T21:26:47.710+0000] {taskinstance.py:731} INFO - ::endgroup::
[2024-11-15T21:26:47.873+0000] {logging_mixin.py:190} INFO - Kunci 'Time Series (Daily)' tidak ditemukan dalam data JSON.
[2024-11-15T21:26:49.361+0000] {log.py:232} WARNING - [nltk_data] Downloading package vader_lexicon to
[nltk_data]     /home/***/nltk_data...
[2024-11-15T21:26:49.364+0000] {log.py:232} WARNING - [nltk_data]   Package vader_lexicon is already up-to-date!
[2024-11-15T21:26:49.429+0000] {taskinstance.py:3311} ERROR - Task failed with exception
Traceback (most recent call last):
  File "/home/airflow/.local/lib/python3.12/site-packages/airflow/models/taskinstance.py", line 767, in _execute_task
    result = _execute_callable(context=context, **execute_callable_kwargs)
             ^^^^^^^^^^^^^^^^^^^^^^^^^^^^^^^^^^^^^^^^^^^^^^^^^^^^^^^^^^^^^
  File "/home/airflow/.local/lib/python3.12/site-packages/airflow/models/taskinstance.py", line 733, in _execute_callable
    return ExecutionCallableRunner(
           ^^^^^^^^^^^^^^^^^^^^^^^^
  File "/home/airflow/.local/lib/python3.12/site-packages/airflow/utils/operator_helpers.py", line 252, in run
    return self.func(*args, **kwargs)
           ^^^^^^^^^^^^^^^^^^^^^^^^^^
  File "/home/airflow/.local/lib/python3.12/site-packages/airflow/models/baseoperator.py", line 417, in wrapper
    return func(self, *args, **kwargs)
           ^^^^^^^^^^^^^^^^^^^^^^^^^^^
  File "/home/airflow/.local/lib/python3.12/site-packages/airflow/operators/python.py", line 238, in execute
    return_value = self.execute_callable()
                   ^^^^^^^^^^^^^^^^^^^^^^^
  File "/home/airflow/.local/lib/python3.12/site-packages/airflow/operators/python.py", line 256, in execute_callable
    return runner.run(*self.op_args, **self.op_kwargs)
           ^^^^^^^^^^^^^^^^^^^^^^^^^^^^^^^^^^^^^^^^^^^
  File "/home/airflow/.local/lib/python3.12/site-packages/airflow/utils/operator_helpers.py", line 252, in run
    return self.func(*args, **kwargs)
           ^^^^^^^^^^^^^^^^^^^^^^^^^^
  File "/opt/airflow/dags/ETL_saham_dag.py", line 63, in process_data
    final_df = transform(df_stock, df_news)
               ^^^^^^^^^^^^^^^^^^^^^^^^^^^^
  File "/opt/airflow/dags/ETL_saham_dag.py", line 82, in transform
    news_df = df_news[['publishedAt', 'title']].copy()
              ~~~~~~~^^^^^^^^^^^^^^^^^^^^^^^^^^
  File "/home/airflow/.local/lib/python3.12/site-packages/pandas/core/frame.py", line 3899, in __getitem__
    indexer = self.columns._get_indexer_strict(key, "columns")[1]
              ^^^^^^^^^^^^^^^^^^^^^^^^^^^^^^^^^^^^^^^^^^^^^^^^
  File "/home/airflow/.local/lib/python3.12/site-packages/pandas/core/indexes/base.py", line 6115, in _get_indexer_strict
    self._raise_if_missing(keyarr, indexer, axis_name)
  File "/home/airflow/.local/lib/python3.12/site-packages/pandas/core/indexes/base.py", line 6176, in _raise_if_missing
    raise KeyError(f"None of [{key}] are in the [{axis_name}]")
KeyError: "None of [Index(['publishedAt', 'title'], dtype='object')] are in the [columns]"
[2024-11-15T21:26:49.527+0000] {logging_mixin.py:190} INFO - Task instance in failure state
[2024-11-15T21:26:49.530+0000] {logging_mixin.py:190} INFO - Task start:2024-11-15 21:26:46.145944+00:00 end:2024-11-15 21:26:49.525440+00:00 duration:3.379496
[2024-11-15T21:26:49.532+0000] {logging_mixin.py:190} INFO - Task:<Task(PythonOperator): process_data> dag:<DAG: stock_sentiment_analysis> dagrun:<DagRun stock_sentiment_analysis @ 2023-10-11 00:00:00+00:00: scheduled__2023-10-11T00:00:00+00:00, state:running, queued_at: 2024-11-15 21:25:26.994254+00:00. externally triggered: False>
[2024-11-15T21:26:49.534+0000] {logging_mixin.py:190} INFO - Failure caused by "None of [Index(['publishedAt', 'title'], dtype='object')] are in the [columns]"
[2024-11-15T21:26:49.536+0000] {taskinstance.py:1225} INFO - Marking task as UP_FOR_RETRY. dag_id=stock_sentiment_analysis, task_id=process_data, run_id=scheduled__2023-10-11T00:00:00+00:00, execution_date=20231011T000000, start_date=20241115T212646, end_date=20241115T212649
[2024-11-15T21:26:49.833+0000] {taskinstance.py:340} INFO - ::group::Post task execution logs
[2024-11-15T21:26:49.840+0000] {standard_task_runner.py:124} ERROR - Failed to execute job 33 for task process_data ("None of [Index(['publishedAt', 'title'], dtype='object')] are in the [columns]"; 232)
Traceback (most recent call last):
  File "/home/airflow/.local/lib/python3.12/site-packages/airflow/task/task_runner/standard_task_runner.py", line 117, in _start_by_fork
    ret = args.func(args, dag=self.dag)
          ^^^^^^^^^^^^^^^^^^^^^^^^^^^^^
  File "/home/airflow/.local/lib/python3.12/site-packages/airflow/cli/cli_config.py", line 49, in command
    return func(*args, **kwargs)
           ^^^^^^^^^^^^^^^^^^^^^
  File "/home/airflow/.local/lib/python3.12/site-packages/airflow/utils/cli.py", line 116, in wrapper
    return f(*args, **kwargs)
           ^^^^^^^^^^^^^^^^^^
  File "/home/airflow/.local/lib/python3.12/site-packages/airflow/cli/commands/task_command.py", line 483, in task_run
    task_return_code = _run_task_by_selected_method(args, _dag, ti)
                       ^^^^^^^^^^^^^^^^^^^^^^^^^^^^^^^^^^^^^^^^^^^^
  File "/home/airflow/.local/lib/python3.12/site-packages/airflow/cli/commands/task_command.py", line 256, in _run_task_by_selected_method
    return _run_raw_task(args, ti)
           ^^^^^^^^^^^^^^^^^^^^^^^
  File "/home/airflow/.local/lib/python3.12/site-packages/airflow/cli/commands/task_command.py", line 341, in _run_raw_task
    return ti._run_raw_task(
           ^^^^^^^^^^^^^^^^^
  File "/home/airflow/.local/lib/python3.12/site-packages/airflow/utils/session.py", line 97, in wrapper
    return func(*args, session=session, **kwargs)
           ^^^^^^^^^^^^^^^^^^^^^^^^^^^^^^^^^^^^^^
  File "/home/airflow/.local/lib/python3.12/site-packages/airflow/models/taskinstance.py", line 3005, in _run_raw_task
    return _run_raw_task(
           ^^^^^^^^^^^^^^
  File "/home/airflow/.local/lib/python3.12/site-packages/airflow/models/taskinstance.py", line 273, in _run_raw_task
    TaskInstance._execute_task_with_callbacks(
  File "/home/airflow/.local/lib/python3.12/site-packages/airflow/models/taskinstance.py", line 3159, in _execute_task_with_callbacks
    result = self._execute_task(context, task_orig)
             ^^^^^^^^^^^^^^^^^^^^^^^^^^^^^^^^^^^^^^
  File "/home/airflow/.local/lib/python3.12/site-packages/airflow/models/taskinstance.py", line 3183, in _execute_task
    return _execute_task(self, context, task_orig)
           ^^^^^^^^^^^^^^^^^^^^^^^^^^^^^^^^^^^^^^^
  File "/home/airflow/.local/lib/python3.12/site-packages/airflow/models/taskinstance.py", line 767, in _execute_task
    result = _execute_callable(context=context, **execute_callable_kwargs)
             ^^^^^^^^^^^^^^^^^^^^^^^^^^^^^^^^^^^^^^^^^^^^^^^^^^^^^^^^^^^^^
  File "/home/airflow/.local/lib/python3.12/site-packages/airflow/models/taskinstance.py", line 733, in _execute_callable
    return ExecutionCallableRunner(
           ^^^^^^^^^^^^^^^^^^^^^^^^
  File "/home/airflow/.local/lib/python3.12/site-packages/airflow/utils/operator_helpers.py", line 252, in run
    return self.func(*args, **kwargs)
           ^^^^^^^^^^^^^^^^^^^^^^^^^^
  File "/home/airflow/.local/lib/python3.12/site-packages/airflow/models/baseoperator.py", line 417, in wrapper
    return func(self, *args, **kwargs)
           ^^^^^^^^^^^^^^^^^^^^^^^^^^^
  File "/home/airflow/.local/lib/python3.12/site-packages/airflow/operators/python.py", line 238, in execute
    return_value = self.execute_callable()
                   ^^^^^^^^^^^^^^^^^^^^^^^
  File "/home/airflow/.local/lib/python3.12/site-packages/airflow/operators/python.py", line 256, in execute_callable
    return runner.run(*self.op_args, **self.op_kwargs)
           ^^^^^^^^^^^^^^^^^^^^^^^^^^^^^^^^^^^^^^^^^^^
  File "/home/airflow/.local/lib/python3.12/site-packages/airflow/utils/operator_helpers.py", line 252, in run
    return self.func(*args, **kwargs)
           ^^^^^^^^^^^^^^^^^^^^^^^^^^
  File "/opt/airflow/dags/ETL_saham_dag.py", line 63, in process_data
    final_df = transform(df_stock, df_news)
               ^^^^^^^^^^^^^^^^^^^^^^^^^^^^
  File "/opt/airflow/dags/ETL_saham_dag.py", line 82, in transform
    news_df = df_news[['publishedAt', 'title']].copy()
              ~~~~~~~^^^^^^^^^^^^^^^^^^^^^^^^^^
  File "/home/airflow/.local/lib/python3.12/site-packages/pandas/core/frame.py", line 3899, in __getitem__
    indexer = self.columns._get_indexer_strict(key, "columns")[1]
              ^^^^^^^^^^^^^^^^^^^^^^^^^^^^^^^^^^^^^^^^^^^^^^^^
  File "/home/airflow/.local/lib/python3.12/site-packages/pandas/core/indexes/base.py", line 6115, in _get_indexer_strict
    self._raise_if_missing(keyarr, indexer, axis_name)
  File "/home/airflow/.local/lib/python3.12/site-packages/pandas/core/indexes/base.py", line 6176, in _raise_if_missing
    raise KeyError(f"None of [{key}] are in the [{axis_name}]")
KeyError: "None of [Index(['publishedAt', 'title'], dtype='object')] are in the [columns]"
[2024-11-15T21:26:49.953+0000] {local_task_job_runner.py:266} INFO - Task exited with return code 1
[2024-11-15T21:26:50.046+0000] {taskinstance.py:3895} INFO - 0 downstream tasks scheduled from follow-on schedule check
[2024-11-15T21:26:50.053+0000] {local_task_job_runner.py:245} INFO - ::endgroup::
