[2024-11-15T21:26:46.793+0000] {local_task_job_runner.py:123} INFO - ::group::Pre task execution logs
[2024-11-15T21:26:47.075+0000] {taskinstance.py:2613} INFO - Dependencies all met for dep_context=non-requeueable deps ti=<TaskInstance: stock_sentiment_analysis.process_data scheduled__2023-10-08T00:00:00+00:00 [queued]>
[2024-11-15T21:26:47.196+0000] {taskinstance.py:2613} INFO - Dependencies all met for dep_context=requeueable deps ti=<TaskInstance: stock_sentiment_analysis.process_data scheduled__2023-10-08T00:00:00+00:00 [queued]>
[2024-11-15T21:26:47.202+0000] {taskinstance.py:2866} INFO - Starting attempt 1 of 2
[2024-11-15T21:26:47.747+0000] {taskinstance.py:2889} INFO - Executing <Task(PythonOperator): process_data> on 2023-10-08 00:00:00+00:00
[2024-11-15T21:26:47.882+0000] {standard_task_runner.py:104} INFO - Running: ['***', 'tasks', 'run', 'stock_sentiment_analysis', 'process_data', 'scheduled__2023-10-08T00:00:00+00:00', '--job-id', '36', '--raw', '--subdir', 'DAGS_FOLDER/ETL_saham_dag.py', '--cfg-path', '/tmp/tmpt8utodxs']
[2024-11-15T21:26:47.899+0000] {standard_task_runner.py:105} INFO - Job 36: Subtask process_data
[2024-11-15T21:26:47.803+0000] {warnings.py:112} WARNING - /home/***/.local/lib/python3.12/site-packages/***/task/task_runner/standard_task_runner.py:70: DeprecationWarning: This process (pid=192) is multi-threaded, use of fork() may lead to deadlocks in the child.
  pid = os.fork()

[2024-11-15T21:26:47.923+0000] {standard_task_runner.py:72} INFO - Started process 247 to run task
[2024-11-15T21:26:48.446+0000] {task_command.py:467} INFO - Running <TaskInstance: stock_sentiment_analysis.process_data scheduled__2023-10-08T00:00:00+00:00 [running]> on host 50375b572a3b
[2024-11-15T21:26:48.931+0000] {taskinstance.py:3132} INFO - Exporting env vars: AIRFLOW_CTX_DAG_OWNER='***' AIRFLOW_CTX_DAG_ID='stock_sentiment_analysis' AIRFLOW_CTX_TASK_ID='process_data' AIRFLOW_CTX_EXECUTION_DATE='2023-10-08T00:00:00+00:00' AIRFLOW_CTX_TRY_NUMBER='1' AIRFLOW_CTX_DAG_RUN_ID='scheduled__2023-10-08T00:00:00+00:00'
[2024-11-15T21:26:48.938+0000] {logging_mixin.py:190} INFO - Task instance is in running state
[2024-11-15T21:26:48.946+0000] {logging_mixin.py:190} INFO -  Previous state of the Task instance: queued
[2024-11-15T21:26:48.953+0000] {logging_mixin.py:190} INFO - Current task name:process_data state:running start_date:2024-11-15 21:26:47.083016+00:00
[2024-11-15T21:26:48.956+0000] {logging_mixin.py:190} INFO - Dag name:stock_sentiment_analysis and current dag run status:running
[2024-11-15T21:26:48.961+0000] {taskinstance.py:731} INFO - ::endgroup::
[2024-11-15T21:26:49.021+0000] {logging_mixin.py:190} INFO - Kunci 'Time Series (Daily)' tidak ditemukan dalam data JSON.
[2024-11-15T21:26:50.171+0000] {log.py:232} WARNING - [nltk_data] Downloading package vader_lexicon to
[nltk_data]     /home/***/nltk_data...
[2024-11-15T21:26:50.174+0000] {log.py:232} WARNING - [nltk_data]   Package vader_lexicon is already up-to-date!
[2024-11-15T21:26:50.229+0000] {taskinstance.py:3311} ERROR - Task failed with exception
Traceback (most recent call last):
  File "/home/airflow/.local/lib/python3.12/site-packages/airflow/models/taskinstance.py", line 767, in _execute_task
    result = _execute_callable(context=context, **execute_callable_kwargs)
             ^^^^^^^^^^^^^^^^^^^^^^^^^^^^^^^^^^^^^^^^^^^^^^^^^^^^^^^^^^^^^
  File "/home/airflow/.local/lib/python3.12/site-packages/airflow/models/taskinstance.py", line 733, in _execute_callable
    return ExecutionCallableRunner(
           ^^^^^^^^^^^^^^^^^^^^^^^^
  File "/home/airflow/.local/lib/python3.12/site-packages/airflow/utils/operator_helpers.py", line 252, in run
    return self.func(*args, **kwargs)
           ^^^^^^^^^^^^^^^^^^^^^^^^^^
  File "/home/airflow/.local/lib/python3.12/site-packages/airflow/models/baseoperator.py", line 417, in wrapper
    return func(self, *args, **kwargs)
           ^^^^^^^^^^^^^^^^^^^^^^^^^^^
  File "/home/airflow/.local/lib/python3.12/site-packages/airflow/operators/python.py", line 238, in execute
    return_value = self.execute_callable()
                   ^^^^^^^^^^^^^^^^^^^^^^^
  File "/home/airflow/.local/lib/python3.12/site-packages/airflow/operators/python.py", line 256, in execute_callable
    return runner.run(*self.op_args, **self.op_kwargs)
           ^^^^^^^^^^^^^^^^^^^^^^^^^^^^^^^^^^^^^^^^^^^
  File "/home/airflow/.local/lib/python3.12/site-packages/airflow/utils/operator_helpers.py", line 252, in run
    return self.func(*args, **kwargs)
           ^^^^^^^^^^^^^^^^^^^^^^^^^^
  File "/opt/airflow/dags/ETL_saham_dag.py", line 63, in process_data
    final_df = transform(df_stock, df_news)
               ^^^^^^^^^^^^^^^^^^^^^^^^^^^^
  File "/opt/airflow/dags/ETL_saham_dag.py", line 82, in transform
    news_df = df_news[['publishedAt', 'title']].copy()
              ~~~~~~~^^^^^^^^^^^^^^^^^^^^^^^^^^
  File "/home/airflow/.local/lib/python3.12/site-packages/pandas/core/frame.py", line 3899, in __getitem__
    indexer = self.columns._get_indexer_strict(key, "columns")[1]
              ^^^^^^^^^^^^^^^^^^^^^^^^^^^^^^^^^^^^^^^^^^^^^^^^
  File "/home/airflow/.local/lib/python3.12/site-packages/pandas/core/indexes/base.py", line 6115, in _get_indexer_strict
    self._raise_if_missing(keyarr, indexer, axis_name)
  File "/home/airflow/.local/lib/python3.12/site-packages/pandas/core/indexes/base.py", line 6176, in _raise_if_missing
    raise KeyError(f"None of [{key}] are in the [{axis_name}]")
KeyError: "None of [Index(['publishedAt', 'title'], dtype='object')] are in the [columns]"
[2024-11-15T21:26:50.357+0000] {logging_mixin.py:190} INFO - Task instance in failure state
[2024-11-15T21:26:50.358+0000] {logging_mixin.py:190} INFO - Task start:2024-11-15 21:26:47.083016+00:00 end:2024-11-15 21:26:50.355742+00:00 duration:3.272726
[2024-11-15T21:26:50.360+0000] {logging_mixin.py:190} INFO - Task:<Task(PythonOperator): process_data> dag:<DAG: stock_sentiment_analysis> dagrun:<DagRun stock_sentiment_analysis @ 2023-10-08 00:00:00+00:00: scheduled__2023-10-08T00:00:00+00:00, state:running, queued_at: 2024-11-15 21:25:25.615062+00:00. externally triggered: False>
[2024-11-15T21:26:50.362+0000] {logging_mixin.py:190} INFO - Failure caused by "None of [Index(['publishedAt', 'title'], dtype='object')] are in the [columns]"
[2024-11-15T21:26:50.365+0000] {taskinstance.py:1225} INFO - Marking task as UP_FOR_RETRY. dag_id=stock_sentiment_analysis, task_id=process_data, run_id=scheduled__2023-10-08T00:00:00+00:00, execution_date=20231008T000000, start_date=20241115T212647, end_date=20241115T212650
[2024-11-15T21:26:50.423+0000] {taskinstance.py:340} INFO - ::group::Post task execution logs
[2024-11-15T21:26:50.427+0000] {standard_task_runner.py:124} ERROR - Failed to execute job 36 for task process_data ("None of [Index(['publishedAt', 'title'], dtype='object')] are in the [columns]"; 247)
Traceback (most recent call last):
  File "/home/airflow/.local/lib/python3.12/site-packages/airflow/task/task_runner/standard_task_runner.py", line 117, in _start_by_fork
    ret = args.func(args, dag=self.dag)
          ^^^^^^^^^^^^^^^^^^^^^^^^^^^^^
  File "/home/airflow/.local/lib/python3.12/site-packages/airflow/cli/cli_config.py", line 49, in command
    return func(*args, **kwargs)
           ^^^^^^^^^^^^^^^^^^^^^
  File "/home/airflow/.local/lib/python3.12/site-packages/airflow/utils/cli.py", line 116, in wrapper
    return f(*args, **kwargs)
           ^^^^^^^^^^^^^^^^^^
  File "/home/airflow/.local/lib/python3.12/site-packages/airflow/cli/commands/task_command.py", line 483, in task_run
    task_return_code = _run_task_by_selected_method(args, _dag, ti)
                       ^^^^^^^^^^^^^^^^^^^^^^^^^^^^^^^^^^^^^^^^^^^^
  File "/home/airflow/.local/lib/python3.12/site-packages/airflow/cli/commands/task_command.py", line 256, in _run_task_by_selected_method
    return _run_raw_task(args, ti)
           ^^^^^^^^^^^^^^^^^^^^^^^
  File "/home/airflow/.local/lib/python3.12/site-packages/airflow/cli/commands/task_command.py", line 341, in _run_raw_task
    return ti._run_raw_task(
           ^^^^^^^^^^^^^^^^^
  File "/home/airflow/.local/lib/python3.12/site-packages/airflow/utils/session.py", line 97, in wrapper
    return func(*args, session=session, **kwargs)
           ^^^^^^^^^^^^^^^^^^^^^^^^^^^^^^^^^^^^^^
  File "/home/airflow/.local/lib/python3.12/site-packages/airflow/models/taskinstance.py", line 3005, in _run_raw_task
    return _run_raw_task(
           ^^^^^^^^^^^^^^
  File "/home/airflow/.local/lib/python3.12/site-packages/airflow/models/taskinstance.py", line 273, in _run_raw_task
    TaskInstance._execute_task_with_callbacks(
  File "/home/airflow/.local/lib/python3.12/site-packages/airflow/models/taskinstance.py", line 3159, in _execute_task_with_callbacks
    result = self._execute_task(context, task_orig)
             ^^^^^^^^^^^^^^^^^^^^^^^^^^^^^^^^^^^^^^
  File "/home/airflow/.local/lib/python3.12/site-packages/airflow/models/taskinstance.py", line 3183, in _execute_task
    return _execute_task(self, context, task_orig)
           ^^^^^^^^^^^^^^^^^^^^^^^^^^^^^^^^^^^^^^^
  File "/home/airflow/.local/lib/python3.12/site-packages/airflow/models/taskinstance.py", line 767, in _execute_task
    result = _execute_callable(context=context, **execute_callable_kwargs)
             ^^^^^^^^^^^^^^^^^^^^^^^^^^^^^^^^^^^^^^^^^^^^^^^^^^^^^^^^^^^^^
  File "/home/airflow/.local/lib/python3.12/site-packages/airflow/models/taskinstance.py", line 733, in _execute_callable
    return ExecutionCallableRunner(
           ^^^^^^^^^^^^^^^^^^^^^^^^
  File "/home/airflow/.local/lib/python3.12/site-packages/airflow/utils/operator_helpers.py", line 252, in run
    return self.func(*args, **kwargs)
           ^^^^^^^^^^^^^^^^^^^^^^^^^^
  File "/home/airflow/.local/lib/python3.12/site-packages/airflow/models/baseoperator.py", line 417, in wrapper
    return func(self, *args, **kwargs)
           ^^^^^^^^^^^^^^^^^^^^^^^^^^^
  File "/home/airflow/.local/lib/python3.12/site-packages/airflow/operators/python.py", line 238, in execute
    return_value = self.execute_callable()
                   ^^^^^^^^^^^^^^^^^^^^^^^
  File "/home/airflow/.local/lib/python3.12/site-packages/airflow/operators/python.py", line 256, in execute_callable
    return runner.run(*self.op_args, **self.op_kwargs)
           ^^^^^^^^^^^^^^^^^^^^^^^^^^^^^^^^^^^^^^^^^^^
  File "/home/airflow/.local/lib/python3.12/site-packages/airflow/utils/operator_helpers.py", line 252, in run
    return self.func(*args, **kwargs)
           ^^^^^^^^^^^^^^^^^^^^^^^^^^
  File "/opt/airflow/dags/ETL_saham_dag.py", line 63, in process_data
    final_df = transform(df_stock, df_news)
               ^^^^^^^^^^^^^^^^^^^^^^^^^^^^
  File "/opt/airflow/dags/ETL_saham_dag.py", line 82, in transform
    news_df = df_news[['publishedAt', 'title']].copy()
              ~~~~~~~^^^^^^^^^^^^^^^^^^^^^^^^^^
  File "/home/airflow/.local/lib/python3.12/site-packages/pandas/core/frame.py", line 3899, in __getitem__
    indexer = self.columns._get_indexer_strict(key, "columns")[1]
              ^^^^^^^^^^^^^^^^^^^^^^^^^^^^^^^^^^^^^^^^^^^^^^^^
  File "/home/airflow/.local/lib/python3.12/site-packages/pandas/core/indexes/base.py", line 6115, in _get_indexer_strict
    self._raise_if_missing(keyarr, indexer, axis_name)
  File "/home/airflow/.local/lib/python3.12/site-packages/pandas/core/indexes/base.py", line 6176, in _raise_if_missing
    raise KeyError(f"None of [{key}] are in the [{axis_name}]")
KeyError: "None of [Index(['publishedAt', 'title'], dtype='object')] are in the [columns]"
[2024-11-15T21:26:50.501+0000] {local_task_job_runner.py:266} INFO - Task exited with return code 1
[2024-11-15T21:26:50.564+0000] {taskinstance.py:3895} INFO - 0 downstream tasks scheduled from follow-on schedule check
[2024-11-15T21:26:50.569+0000] {local_task_job_runner.py:245} INFO - ::endgroup::
