[2024-11-15T23:07:02.837+0000] {local_task_job_runner.py:123} INFO - ::group::Pre task execution logs
[2024-11-15T23:07:02.888+0000] {taskinstance.py:2613} INFO - Dependencies all met for dep_context=non-requeueable deps ti=<TaskInstance: stock_sentiment_testing_2.load_data scheduled__2024-11-14T00:00:00+00:00 [queued]>
[2024-11-15T23:07:02.905+0000] {taskinstance.py:2613} INFO - Dependencies all met for dep_context=requeueable deps ti=<TaskInstance: stock_sentiment_testing_2.load_data scheduled__2024-11-14T00:00:00+00:00 [queued]>
[2024-11-15T23:07:02.906+0000] {taskinstance.py:2866} INFO - Starting attempt 3 of 4
[2024-11-15T23:07:02.929+0000] {taskinstance.py:2889} INFO - Executing <Task(PythonOperator): load_data> on 2024-11-14 00:00:00+00:00
[2024-11-15T23:07:02.942+0000] {warnings.py:112} WARNING - /home/***/.local/lib/python3.12/site-packages/***/task/task_runner/standard_task_runner.py:70: DeprecationWarning: This process (pid=2466) is multi-threaded, use of fork() may lead to deadlocks in the child.
  pid = os.fork()

[2024-11-15T23:07:02.945+0000] {standard_task_runner.py:72} INFO - Started process 2468 to run task
[2024-11-15T23:07:02.945+0000] {standard_task_runner.py:104} INFO - Running: ['***', 'tasks', 'run', 'stock_sentiment_testing_2', 'load_data', 'scheduled__2024-11-14T00:00:00+00:00', '--job-id', '286', '--raw', '--subdir', 'DAGS_FOLDER/ETL_saham_test2.py', '--cfg-path', '/tmp/tmpsqmd9y39']
[2024-11-15T23:07:02.947+0000] {standard_task_runner.py:105} INFO - Job 286: Subtask load_data
[2024-11-15T23:07:03.027+0000] {task_command.py:467} INFO - Running <TaskInstance: stock_sentiment_testing_2.load_data scheduled__2024-11-14T00:00:00+00:00 [running]> on host 50375b572a3b
[2024-11-15T23:07:03.161+0000] {taskinstance.py:3132} INFO - Exporting env vars: AIRFLOW_CTX_DAG_OWNER='***' AIRFLOW_CTX_DAG_ID='stock_sentiment_testing_2' AIRFLOW_CTX_TASK_ID='load_data' AIRFLOW_CTX_EXECUTION_DATE='2024-11-14T00:00:00+00:00' AIRFLOW_CTX_TRY_NUMBER='3' AIRFLOW_CTX_DAG_RUN_ID='scheduled__2024-11-14T00:00:00+00:00'
[2024-11-15T23:07:03.164+0000] {logging_mixin.py:190} INFO - Task instance is in running state
[2024-11-15T23:07:03.165+0000] {logging_mixin.py:190} INFO -  Previous state of the Task instance: queued
[2024-11-15T23:07:03.166+0000] {logging_mixin.py:190} INFO - Current task name:load_data state:running start_date:2024-11-15 23:07:02.889915+00:00
[2024-11-15T23:07:03.167+0000] {logging_mixin.py:190} INFO - Dag name:stock_sentiment_testing_2 and current dag run status:running
[2024-11-15T23:07:03.169+0000] {taskinstance.py:731} INFO - ::endgroup::
[2024-11-15T23:07:03.195+0000] {taskinstance.py:3311} ERROR - Task failed with exception
Traceback (most recent call last):
  File "/home/airflow/.local/lib/python3.12/site-packages/airflow/models/taskinstance.py", line 767, in _execute_task
    result = _execute_callable(context=context, **execute_callable_kwargs)
             ^^^^^^^^^^^^^^^^^^^^^^^^^^^^^^^^^^^^^^^^^^^^^^^^^^^^^^^^^^^^^
  File "/home/airflow/.local/lib/python3.12/site-packages/airflow/models/taskinstance.py", line 733, in _execute_callable
    return ExecutionCallableRunner(
           ^^^^^^^^^^^^^^^^^^^^^^^^
  File "/home/airflow/.local/lib/python3.12/site-packages/airflow/utils/operator_helpers.py", line 252, in run
    return self.func(*args, **kwargs)
           ^^^^^^^^^^^^^^^^^^^^^^^^^^
  File "/home/airflow/.local/lib/python3.12/site-packages/airflow/models/baseoperator.py", line 417, in wrapper
    return func(self, *args, **kwargs)
           ^^^^^^^^^^^^^^^^^^^^^^^^^^^
  File "/home/airflow/.local/lib/python3.12/site-packages/airflow/operators/python.py", line 238, in execute
    return_value = self.execute_callable()
                   ^^^^^^^^^^^^^^^^^^^^^^^
  File "/home/airflow/.local/lib/python3.12/site-packages/airflow/operators/python.py", line 256, in execute_callable
    return runner.run(*self.op_args, **self.op_kwargs)
           ^^^^^^^^^^^^^^^^^^^^^^^^^^^^^^^^^^^^^^^^^^^
  File "/home/airflow/.local/lib/python3.12/site-packages/airflow/utils/operator_helpers.py", line 252, in run
    return self.func(*args, **kwargs)
           ^^^^^^^^^^^^^^^^^^^^^^^^^^
  File "/opt/airflow/dags/ETL_saham_test2.py", line 133, in load_data
    raise ValueError("No data found in XComs.")
ValueError: No data found in XComs.
[2024-11-15T23:07:03.232+0000] {logging_mixin.py:190} INFO - Task instance in failure state
[2024-11-15T23:07:03.234+0000] {logging_mixin.py:190} INFO - Task start:2024-11-15 23:07:02.889915+00:00 end:2024-11-15 23:07:03.230825+00:00 duration:0.34091
[2024-11-15T23:07:03.236+0000] {logging_mixin.py:190} INFO - Task:<Task(PythonOperator): load_data> dag:<DAG: stock_sentiment_testing_2> dagrun:<DagRun stock_sentiment_testing_2 @ 2024-11-14 00:00:00+00:00: scheduled__2024-11-14T00:00:00+00:00, state:running, queued_at: 2024-11-15 23:06:58.559353+00:00. externally triggered: False>
[2024-11-15T23:07:03.237+0000] {logging_mixin.py:190} INFO - Failure caused by No data found in XComs.
[2024-11-15T23:07:03.239+0000] {taskinstance.py:1225} INFO - Marking task as UP_FOR_RETRY. dag_id=stock_sentiment_testing_2, task_id=load_data, run_id=scheduled__2024-11-14T00:00:00+00:00, execution_date=20241114T000000, start_date=20241115T230702, end_date=20241115T230703
[2024-11-15T23:07:03.278+0000] {taskinstance.py:340} INFO - ::group::Post task execution logs
[2024-11-15T23:07:03.281+0000] {standard_task_runner.py:124} ERROR - Failed to execute job 286 for task load_data (No data found in XComs.; 2468)
Traceback (most recent call last):
  File "/home/airflow/.local/lib/python3.12/site-packages/airflow/task/task_runner/standard_task_runner.py", line 117, in _start_by_fork
    ret = args.func(args, dag=self.dag)
          ^^^^^^^^^^^^^^^^^^^^^^^^^^^^^
  File "/home/airflow/.local/lib/python3.12/site-packages/airflow/cli/cli_config.py", line 49, in command
    return func(*args, **kwargs)
           ^^^^^^^^^^^^^^^^^^^^^
  File "/home/airflow/.local/lib/python3.12/site-packages/airflow/utils/cli.py", line 116, in wrapper
    return f(*args, **kwargs)
           ^^^^^^^^^^^^^^^^^^
  File "/home/airflow/.local/lib/python3.12/site-packages/airflow/cli/commands/task_command.py", line 483, in task_run
    task_return_code = _run_task_by_selected_method(args, _dag, ti)
                       ^^^^^^^^^^^^^^^^^^^^^^^^^^^^^^^^^^^^^^^^^^^^
  File "/home/airflow/.local/lib/python3.12/site-packages/airflow/cli/commands/task_command.py", line 256, in _run_task_by_selected_method
    return _run_raw_task(args, ti)
           ^^^^^^^^^^^^^^^^^^^^^^^
  File "/home/airflow/.local/lib/python3.12/site-packages/airflow/cli/commands/task_command.py", line 341, in _run_raw_task
    return ti._run_raw_task(
           ^^^^^^^^^^^^^^^^^
  File "/home/airflow/.local/lib/python3.12/site-packages/airflow/utils/session.py", line 97, in wrapper
    return func(*args, session=session, **kwargs)
           ^^^^^^^^^^^^^^^^^^^^^^^^^^^^^^^^^^^^^^
  File "/home/airflow/.local/lib/python3.12/site-packages/airflow/models/taskinstance.py", line 3005, in _run_raw_task
    return _run_raw_task(
           ^^^^^^^^^^^^^^
  File "/home/airflow/.local/lib/python3.12/site-packages/airflow/models/taskinstance.py", line 273, in _run_raw_task
    TaskInstance._execute_task_with_callbacks(
  File "/home/airflow/.local/lib/python3.12/site-packages/airflow/models/taskinstance.py", line 3159, in _execute_task_with_callbacks
    result = self._execute_task(context, task_orig)
             ^^^^^^^^^^^^^^^^^^^^^^^^^^^^^^^^^^^^^^
  File "/home/airflow/.local/lib/python3.12/site-packages/airflow/models/taskinstance.py", line 3183, in _execute_task
    return _execute_task(self, context, task_orig)
           ^^^^^^^^^^^^^^^^^^^^^^^^^^^^^^^^^^^^^^^
  File "/home/airflow/.local/lib/python3.12/site-packages/airflow/models/taskinstance.py", line 767, in _execute_task
    result = _execute_callable(context=context, **execute_callable_kwargs)
             ^^^^^^^^^^^^^^^^^^^^^^^^^^^^^^^^^^^^^^^^^^^^^^^^^^^^^^^^^^^^^
  File "/home/airflow/.local/lib/python3.12/site-packages/airflow/models/taskinstance.py", line 733, in _execute_callable
    return ExecutionCallableRunner(
           ^^^^^^^^^^^^^^^^^^^^^^^^
  File "/home/airflow/.local/lib/python3.12/site-packages/airflow/utils/operator_helpers.py", line 252, in run
    return self.func(*args, **kwargs)
           ^^^^^^^^^^^^^^^^^^^^^^^^^^
  File "/home/airflow/.local/lib/python3.12/site-packages/airflow/models/baseoperator.py", line 417, in wrapper
    return func(self, *args, **kwargs)
           ^^^^^^^^^^^^^^^^^^^^^^^^^^^
  File "/home/airflow/.local/lib/python3.12/site-packages/airflow/operators/python.py", line 238, in execute
    return_value = self.execute_callable()
                   ^^^^^^^^^^^^^^^^^^^^^^^
  File "/home/airflow/.local/lib/python3.12/site-packages/airflow/operators/python.py", line 256, in execute_callable
    return runner.run(*self.op_args, **self.op_kwargs)
           ^^^^^^^^^^^^^^^^^^^^^^^^^^^^^^^^^^^^^^^^^^^
  File "/home/airflow/.local/lib/python3.12/site-packages/airflow/utils/operator_helpers.py", line 252, in run
    return self.func(*args, **kwargs)
           ^^^^^^^^^^^^^^^^^^^^^^^^^^
  File "/opt/airflow/dags/ETL_saham_test2.py", line 133, in load_data
    raise ValueError("No data found in XComs.")
ValueError: No data found in XComs.
[2024-11-15T23:07:03.324+0000] {local_task_job_runner.py:266} INFO - Task exited with return code 1
[2024-11-15T23:07:03.372+0000] {taskinstance.py:3895} INFO - 0 downstream tasks scheduled from follow-on schedule check
[2024-11-15T23:07:03.378+0000] {local_task_job_runner.py:245} INFO - ::endgroup::
